Workbook

Sheet Instructions
A1: ISA/IEC 62443 OT Cyber-Physical Security Assurance Test Tracker v2.0
A2: Copyright (c) 2026 Isiah Jones. All Rights Reserved.
A4: Tab Descriptions
A5: Requirements Library | B5: All ISA/IEC 62443-3-3 SRs, 62443-4-2 EDR/HDR/NDR/SAR component requirements, and PLC Top 20 Secure Coding Practices with full FR names and SL mappings.
A6: MITRE ATT&CK ICS | B6: Complete ATT&CK for ICS techniques with ID+Name, tactics, descriptions. Feeds dropdown in Test Tracker.
A7: Asset Inventory | B7: Track all assets under test (systems, components, zones, conduits). Feeds the Asset Under Test dropdown in Test Tracker.
A8: Test Tracker | B8: Main testing worksheet. All dropdowns pull from reference tabs. Includes ATT&CK Impact, CyberPHA/HAZOP/FMEA consequences, and ATT&CK vulnerability types.
A9: CVSS v4.0 Reference | B9: Reference for CVSS v4.0 metrics. Use https://www.first.org/cvss/calculator/4.0 for scoring.
A10: Risk Matrix | B10: 5x5 risk matrix and Assurance Decision Framework with CVSS-to-assurance level mapping.
A11: POA&M Tracker | B11: Plan of Action and Milestones for tracking remediation of findings from testing.
A12: Metrics Dashboard | B12: Auto-calculated metrics with charts: test status, risk ranking, FR coverage by risk level, ATT&CK Impact distribution, consequence type distribution.
A13: Report Template | B13: Executive summary template with auto-populated stats and four assurance decision statements.
A15: Standards References
A16: ISA/IEC 62443-3-3 | B16: System Security Requirements and Security Levels
A17: ISA/IEC 62443-4-2 | B17: Technical Security Requirements for IACS Components (EDR/HDR/NDR/SAR)
A18: PLC Top 20 | B18: Secure PLC Coding Practices — https://plc-security.com
A19: MITRE ATT&CK for ICS | B19: https://attack.mitre.org/matrices/ics/
A20: CVSS v4.0 | B20: https://www.first.org/cvss/calculator/4.0

Sheet Requirements Library
A1: Req_ID | B1: Standard | C1: Section | D1: FR/Category | E1: Requirement Name | F1: Type | G1: Base Requirement Description | H1: Requirement Enhancement | I1: RE Description | J1: SL-1 | K1: SL-2 | L1: SL-3 | M1: SL-4 | N1: Applicable Component Types
A2: SR 1.1 | B2: 62443-3-3 | C2: 5.3 | D2: FR1 - Identification and Authentication Control (IAC) | E2: Human User Identification and Authentication | F2: System Req (SR) | G2: Identify and authenticate all human users on all interfaces. | H2: RE1: Unique ID+auth; RE2: MFA untrusted nets; RE3: MFA all nets | J2: Y | K2: Y+RE1 | L2: Y+RE1+RE2 | M2: Y+RE1+RE2+RE3 | N2: Host, Application, Network
A3: SR 1.2 | B3: 62443-3-3 | C3: 5.4 | D3: FR1 - Identification and Authentication Control (IAC) | E3: Software Process and Device Identification and Authentication | F3: System Req (SR) | G3: Identify and authenticate all software processes and devices. | H3: RE1: Unique ID+auth | J3: N/S | K3: Y | L3: Y+RE1 | M3: Y+RE1 | N3: Embedded, Host, Network
A4: SR 1.3 | B4: 62443-3-3 | C4: 5.5 | D4: FR1 - Identification and Authentication Control (IAC) | E4: Account Management | F4: System Req (SR) | G4: Support management of all accounts by authorized users. | H4: RE1: Unified account mgmt | J4: Y | K4: Y | L4: Y+RE1 | M4: Y+RE1 | N4: Host, Application
A5: SR 1.4 | B5: 62443-3-3 | C5: 5.6 | D5: FR1 - Identification and Authentication Control (IAC) | E5: Identifier Management | F5: System Req (SR) | G5: Support management of identifiers by user, group, role or interface. | H5: None | J5: Y | K5: Y | L5: Y | M5: Y | N5: All
A6: SR 1.5 | B6: 62443-3-3 | C6: 5.7 | D6: FR1 - Identification and Authentication Control (IAC) | E6: Authenticator Management | F6: System Req (SR) | G6: Initialize, change, refresh, and protect all authenticators. | H6: RE1: HW security for SW process credentials | J6: Y | K6: Y | L6: Y+RE1 | M6: Y+RE1 | N6: All
A7: SR 1.6 | B7: 62443-3-3 | C7: 5.8 | D7: FR1 - Identification and Authentication Control (IAC) | E7: Wireless Access Management | F7: System Req (SR) | G7: Identify and authenticate all wireless users. | H7: RE1: Unique wireless ID+auth | J7: Y | K7: Y+RE1 | L7: Y+RE1 | M7: Y+RE1 | N7: Network, Embedded
A8: SR 1.7 | B8: 62443-3-3 | C8: 5.9 | D8: FR1 - Identification and Authentication Control (IAC) | E8: Strength of Password-Based Authentication | F8: System Req (SR) | G8: Enforce configurable password strength. | H8: RE1: Password generation/lifetime for humans; RE2: Lifetime for all users | J8: Y | K8: Y | L8: Y+RE1 | M8: Y+RE1+RE2 | N8: Host, Application
A9: SR 1.8 | B9: 62443-3-3 | C9: 5.10 | D9: FR1 - Identification and Authentication Control (IAC) | E9: Public Key Infrastructure (PKI) Certificates | F9: System Req (SR) | G9: Operate PKI per best practices or obtain certificates from existing PKI. | H9: None | J9: N/S | K9: Y | L9: Y | M9: Y | N9: Host, Network
A10: SR 1.9 | B10: 62443-3-3 | C10: 5.11 | D10: FR1 - Identification and Authentication Control (IAC) | E10: Strength of Public Key Authentication | F10: System Req (SR) | G10: Validate certificates, control private keys, map identity to users. | H10: RE1: HW security for public key auth | J10: N/S | K10: Y | L10: Y+RE1 | M10: Y+RE1 | N10: Host, Network
A11: SR 1.10 | B11: 62443-3-3 | C11: 5.12 | D11: FR1 - Identification and Authentication Control (IAC) | E11: Authenticator Feedback | F11: System Req (SR) | G11: Obscure feedback of authentication information. | H11: None | J11: Y | K11: Y | L11: Y | M11: Y | N11: All
A12: SR 1.11 | B12: 62443-3-3 | C12: 5.13 | D12: FR1 - Identification and Authentication Control (IAC) | E12: Unsuccessful Login Attempts | F12: System Req (SR) | G12: Enforce limit of consecutive invalid access attempts. | H12: None | J12: Y | K12: Y | L12: Y | M12: Y | N12: Host, Application
A13: SR 1.12 | B13: 62443-3-3 | C13: 5.14 | D13: FR1 - Identification and Authentication Control (IAC) | E13: System Use Notification | F13: System Req (SR) | G13: Display system use notification before authenticating. | H13: None | J13: Y | K13: Y | L13: Y | M13: Y | N13: Host, Application
... A82: SAR 3.8 | B82: 62443-4-2 | C82: 14.7 | D82: FR3 - System Integrity (SI) | E82: Session Integrity (Application) | F82: Software Application Req (SAR) | G82: Application shall protect session integrity. | H82: Maps to SR 3.8 | J82: N/S | K82: Y | L82: Y+RE1+RE2 | M82: Y+RE1+RE2+RE3 | N82: Applications
A83: PLC-01 | B83: PLC Top 20 | C83: Practice 1 | D83: PLC Top 20 Secure Coding Practices | E83: Modularize PLC Code | F83: Secure Coding Practice | G83: Split PLC code into modules to limit effect of compromise. | J83: Y | K83: Y | L83: Y | M83: Y | N83: PLC/DCS/RTU
A84: PLC-02 | B84: PLC Top 20 | C84: Practice 2 | D84: PLC Top 20 Secure Coding Practices | E84: Track Operating Modes | F84: Secure Coding Practice | G84: Track PLC operating mode (Run/Program/Test) and alarm on changes. | J84: Y | K84: Y | L84: Y | M84: Y | N84: PLC/DCS/RTU
A85: PLC-03 | B85: PLC Top 20 | C85: Practice 3 | D85: PLC Top 20 Secure Coding Practices | E85: Leave Operational Logic in the PLC | F85: Secure Coding Practice | G85: Avoid placing safety-critical logic in HMI/SCADA; only PLC hosts it. | J85: Y | K85: Y | L85: Y | M85: Y | N85: PLC/DCS/RTU
A86: PLC-04 | B86: PLC Top 20 | C86: Practice 4 | D86: PLC Top 20 Secure Coding Practices | E86: Use PLC Flags as Integrity Checks | F86: Secure Coding Practice | G86: Use internal flags and watchdog timers to monitor code execution integrity. | J86: Y | K86: Y | L86: Y | M86: Y | N86: PLC/DCS/RTU
A87: PLC-05 | B87: PLC Top 20 | C87: Practice 5 | D87: PLC Top 20 Secure Coding Practices | E87: Use Cryptographic/Checksum Integrity Checks | F87: Secure Coding Practice | G87: Verify PLC program integrity at startup and periodically via hashes/checksums. | J87: Y | K87: Y | L87: Y | M87: Y | N87: PLC/DCS/RTU
A88: PLC-06 | B88: PLC Top 20 | C88: Practice 6 | D88: PLC Top 20 Secure Coding Practices | E88: Validate Timers and Counters | F88: Secure Coding Practice | G88: Validate timers/counters in safety-critical functions to detect manipulation. | J88: Y | K88: Y | L88: Y | M88: Y | N88: PLC/DCS/RTU
A89: PLC-07 | B89: PLC Top 20 | C89: Practice 7 | D89: PLC Top 20 Secure Coding Practices | E89: Validate Paired Inputs/Outputs | F89: Secure Coding Practice | G89: Cross-check related I/O to detect inconsistencies indicating tampering. | J89: Y | K89: Y | L89: Y | M89: Y | N89: PLC/DCS/RTU
A90: PLC-08 | B90: PLC Top 20 | C90: Practice 8 | D90: PLC Top 20 Secure Coding Practices | E90: Validate Input/Output Data | F90: Secure Coding Practice | G90: Validate I/O against expected ranges; alert on out-of-range values. | J90: Y | K90: Y | L90: Y | M90: Y | N90: PLC/DCS/RTU
A91: PLC-09 | B91: PLC Top 20 | C91: Practice 9 | D91: PLC Top 20 Secure Coding Practices | E91: Validate HMI Input Variables at PLC Level | F91: Secure Coding Practice | G91: Do not trust setpoint/command values from HMI without PLC-level validation. | J91: Y | K91: Y | L91: Y | M91: Y | N91: PLC/DCS/RTU
A92: PLC-10 | B92: PLC Top 20 | C92: Practice 10 | D92: PLC Top 20 Secure Coding Practices | E92: Validate Indications by Checking Field Device Responses | F92: Secure Coding Practice | G92: Validate field device responses match commands sent. | J92: Y | K92: Y | L92: Y | M92: Y | N92: PLC/DCS/RTU
A93: PLC-11 | B93: PLC Top 20 | C93: Practice 11 | D93: PLC Top 20 Secure Coding Practices | E93: Define a Safe Process State | F93: Secure Coding Practice | G93: Define/implement safe process state PLC reverts to on anomaly detection. | J93: Y | K93: Y | L93: Y | M93: Y | N93: PLC/DCS/RTU
A94: PLC-12 | B94: PLC Top 20 | C94: Practice 12 | D94: PLC Top 20 Secure Coding Practices | E94: Monitor PLC Uptime | F94: Secure Coding Practice | G94: Track and report PLC uptime to detect unexpected restarts. | J94: Y | K94: Y | L94: Y | M94: Y | N94: PLC/DCS/RTU
... A102: PLC-20 | B102: PLC Top 20 | C102: Practice 20 | D102: PLC Top 20 Secure Coding Practices | E102: Instrument for Forensics | F102: Secure Coding Practice | G102: Provide sufficient logging/diagnostics in PLC for post-incident forensics. | J102: Y | K102: Y | L102: Y | M102: Y | N102: PLC/DCS/RTU

Sheet MITRE ATT&CK ICS
A1: Technique ID | B1: Technique Name | C1: Tactic | D1: Description Summary | E1: ID + Name
A2: T0800 | B2: Activate Firmware Update Mode | C2: Inhibit Response Function | D2: Activate firmware update mode to prevent response functions | E2: T0800 Activate Firmware Update Mode
A3: T0801 | B3: Monitor Process State | C3: Collection | D3: Gather information about physical process state | E3: T0801 Monitor Process State
A4: T0802 | B4: Automated Collection | C4: Collection | D4: Automate collection of ICS environment information | E4: T0802 Automated Collection
A5: T0803 | B5: Block Command Message | C5: Inhibit Response Function | D5: Block command messages from reaching target devices | E5: T0803 Block Command Message
A6: T0804 | B6: Block Reporting Message | C6: Inhibit Response Function | D6: Block reporting messages to hide actions from operator | E6: T0804 Block Reporting Message
A7: T0805 | B7: Block Serial COM | C7: Inhibit Response Function | D7: Block access to serial COM ports | E7: T0805 Block Serial COM
A8: T0806 | B8: Brute Force I/O | C8: Impair Process Control | D8: Repetitively change I/O point values to manipulate process | E8: T0806 Brute Force I/O
A9: T0807 | B9: Command-Line Interface | C9: Execution | D9: Use CLIs to interact with systems and execute commands | E9: T0807 Command-Line Interface
A10: T0809 | B10: Data Destruction | C10: Inhibit Response Function | D10: Destroy data over course of an operation | E10: T0809 Data Destruction
A11: T0811 | B11: Data from Information Repositories | C11: Collection | D11: Collect data from information repositories | E11: T0811 Data from Information Repositories
A12: T0812 | B12: Default Credentials | C12: Lateral Movement | D12: Leverage default credentials on control system devices | E12: T0812 Default Credentials
... A85: T1695 | B85: Block Communications | C85: Inhibit Response Function | D85: Block OT communications to disrupt processes | E85: T1695 Block Communications

Sheet Asset Inventory
A1: Asset ID | B1: System Type | C1: Asset Name | D1: Manufacturer | E1: Model | F1: FW/SW Version | G1: Network Zone | H1: Conduit ID | I1: Purdue Level | J1: SIL/Criticality | K1: Protocol(s) | L1: Physical Location | M1: IP Address | N1: Asset Display Name
A2: ASSET-001 | B2: SIS | C2: Asset BMS | N2: ASSET-001 | SIS
A3: ASSET-002 | B3: BPCS | N3: ASSET-002 | BPCS
A4: ASSET-003 | B4: DCS | N4: ASSET-003 | DCS
A5: ASSET-004 | B5: PLC | N5: ASSET-004 | PLC
A6: ASSET-005 | B6: RTU | N6: ASSET-005 | RTU
A7: ASSET-006 | B7: IED | N7: ASSET-006 | IED
A8: ASSET-007 | B8: HMI | N8: ASSET-007 | HMI
A9: ASSET-008 | B9: EWS | N9: ASSET-008 | EWS
A10: ASSET-009 | B10: OWS | N10: ASSET-009 | OWS
A11: ASSET-010 | B11: Data Historian | N11: ASSET-010 | Data Historian
A12: ASSET-011 | B12: Application Server | N12: ASSET-011 | Application Server
A13: ASSET-012 | B13: Domain Controller | N13: ASSET-012 | Domain Controller
A14: ASSET-013 | B14: Network Switch | N14: ASSET-013 | Network Switch
... A28: ASSET-027 | B28: DMZ Server | N28: ASSET-027 | DMZ Server

Sheet Test Tracker
A1: Test ID | B1: Requirement ID | C1: Standard | D1: FR/Category | E1: Requirement Name | F1: Target SL | G1: Asset Type Under Test | H1: Asset Name | I1: CVSS v4.0 Base Score | J1: CVSS v4.0 Severity | K1: CVSS v4.0 Vector String | L1: Risk Ranking | M1: Tester Name | N1: Tester Organization | O1: Tester Role | P1: Test Date/Time | Q1: Test Method | R1: Tools Used | S1: Expected Results | T1: Actual Results | U1: Test Status | V1: Artifacts Collected | W1: Evidence Reference | X1: Compensating Controls | Y1: Findings/Observations | Z1: Recommendations | AA1: Impact (ATT&CK ICS) | AB1: Consequence (CyberPHA/HAZOP) | AC1: Likelihood | AD1: Vulnerability Type (ATT&CK ICS) | AE1: Threat Level
A2: TST-0001
A3: TST-0002
A4: TST-0003
A5: TST-0004
A6: TST-0005
A7: TST-0006
A8: TST-0007
A9: TST-0008
A10: TST-0009
A11: TST-0010
A12: TST-0011
A13: TST-0012
... A101: TST-0100

Sheet CVSS v4.0 Reference
A1: Metric Group | B1: Metric | C1: ID | D1: Value Options | E1: Description
A2: Base-Exploitability | B2: Attack Vector | C2: AV | D2: Network(N),Adjacent(A),Local(L),Physical(P) | E2: How vulnerability is exploited
A3: Base-Exploitability | B3: Attack Complexity | C3: AC | D3: Low(L),High(H) | E3: Conditions beyond attacker control
A4: Base-Exploitability | B4: Attack Requirements | C4: AT | D4: None(N),Present(P) | E4: Prerequisites for attack
A5: Base-Exploitability | B5: Privileges Required | C5: PR | D5: None(N),Low(L),High(H) | E5: Privilege level needed
A6: Base-Exploitability | B6: User Interaction | C6: UI | D6: None(N),Passive(P),Active(A) | E6: User interaction needed
A7: Base-Vulnerable Sys | B7: Confidentiality (VC) | C7: VC | D7: None(N),Low(L),High(H) | E7: C impact to vulnerable system
A8: Base-Vulnerable Sys | B8: Integrity (VI) | C8: VI | D8: None(N),Low(L),High(H) | E8: I impact to vulnerable system
A9: Base-Vulnerable Sys | B9: Availability (VA) | C9: VA | D9: None(N),Low(L),High(H) | E9: A impact to vulnerable system
A10: Base-Subsequent Sys | B10: Confidentiality (SC) | C10: SC | D10: None(N),Low(L),High(H) | E10: C impact to subsequent system
A11: Base-Subsequent Sys | B11: Integrity (SI) | C11: SI | D11: None(N),Low(L),High(H) | E11: I impact to subsequent system
A12: Base-Subsequent Sys | B12: Availability (SA) | C12: SA | D12: None(N),Low(L),High(H) | E12: A impact to subsequent system
... A16: Threat | B16: Exploit Maturity | C16: E | D16: Not Defined(X),Attacked(A),POC(P),Unreported(U) | E16: Exploit availability

Sheet Risk Matrix
A1: OT Cyber-Physical Security Risk Assessment Matrix
A3: Likelihood \ Impact | B3: Catastrophic | C3: Critical | D3: Major | E3: Moderate | F3: Minor
A4: Almost Certain | B4: Critical | C4: Critical | D4: Critical | E4: High | F4: High
A5: Likely | B5: Critical | C5: Critical | D5: High | E5: High | F5: Medium
A6: Possible | B6: Critical | C6: High | D6: High | E6: Medium | F6: Medium
A7: Unlikely | B7: High | C7: High | D7: Medium | E7: Medium | F7: Low
A8: Rare | B8: High | C8: Medium | D8: Low | E8: Low | F8: Low
A11: Security Assurance Decision Framework
A13: Decision Level | B13: Criteria | C13: CVSS v4.0 Range | D13: Risk Level | E13: Conditions | F13: Action
A14: Rejection | B14: Fails minimum SL-3; critical/high unmitigated | C14: >=9.0 | D14: Critical | E14: Critical finding without compensating controls | F14: Do not deploy. Remediate and retest.
A15: Limited Assurance | B15: Meets SL-3; high findings with compensating controls | C15: 7.0-8.9 | D15: High | E15: High findings with documented compensating controls + 30 day POA&M | F15: Conditional deployment with monitoring + 30 mitigation POA&M.
A16: Conditional Assurance | B16: Meets target SL; medium findings with mitigations | C16: 4.0-6.9 | D16: Medium | E16: Medium findings with 60 day remediation timeline | F16: Deploy with conditions and scheduled reassessment. 60 day mitigation POAM
A17: Reasonable Assurance | B17: Meets/exceeds target SL; low/informational only | C17: 0.0-3.9 | D17: Low/None | E17: No unmitigated findings above Low | F17: Full deployment authorization. 6-12 month mitigation POAM

Sheet POA&M Tracker
A1: POA&M ID | B1: Source | C1: Test ID Ref | D1: Description | E1: Affected System(s) | F1: Risk Level | G1: CVSS v4.0 Score | H1: Corrective Action | I1: Responsible Owner | J1: Target Date | K1: Status | L1: Days Open | M1: Completion Date | N1: Verification Method | O1: Notes
A2: POAM-001 | L2: =IF(AND(K2<>"Closed",J2<>""),MAX(0,TODAY()-J2),"")
A3: POAM-002 | L3: =IF(AND(K3<>"Closed",J3<>""),MAX(0,TODAY()-J3),"")
A4: POAM-003 | L4: =IF(AND(K4<>"Closed",J4<>""),MAX(0,TODAY()-J4),"")
A5: POAM-004 | L5: =IF(AND(K5<>"Closed",J5<>""),MAX(0,TODAY()-J5),"")
A6: POAM-005 | L6: =IF(AND(K6<>"Closed",J6<>""),MAX(0,TODAY()-J6),"")
A7: POAM-006 | L7: =IF(AND(K7<>"Closed",J7<>""),MAX(0,TODAY()-J7),"")
A8: POAM-007 | L8: =IF(AND(K8<>"Closed",J8<>""),MAX(0,TODAY()-J8),"")
A9: POAM-008 | L9: =IF(AND(K9<>"Closed",J9<>""),MAX(0,TODAY()-J9),"")
A10: POAM-009 | L10: =IF(AND(K10<>"Closed",J10<>""),MAX(0,TODAY()-J10),"")
A11: POAM-010 | L11: =IF(AND(K11<>"Closed",J11<>""),MAX(0,TODAY()-J11),"")
A12: POAM-011 | L12: =IF(AND(K12<>"Closed",J12<>""),MAX(0,TODAY()-J12),"")
A13: POAM-012 | L13: =IF(AND(K13<>"Closed",J13<>""),MAX(0,TODAY()-J13),"")
... A51: POAM-050 | L51: =IF(AND(K51<>"Closed",J51<>""),MAX(0,TODAY()-J51),"")

Sheet Metrics Dashboard
A1: OT Cyber-Physical Security Assurance Test Metrics Dashboard
A3: Test Status Summary | B3: Count | C3: % | E3: FR Coverage by Risk Ranking
A4: Total Tested | B4: =COUNTA('Test Tracker'!U2:U101)-COUNTBLANK('Test Tracker'!U2:U101) -> -100 | E4: FR/Category | F4: Tests | G4: Critical | H4: High | I4: Medium | J4: Low | K4: Pass
A5: Pass | B5: =COUNTIF('Test Tracker'!U2:U101,"Pass") -> 0 | C5: =IF(B4=0,0,B5/B4) -> 0 | E5: FR1 - Identification and Authentication | F5: =COUNTIF('Test Tracker'!D2:D101,"FR1 - Identification and Authentication Control (IAC)") -> 0 | G5: =COUNTIFS('Test Tracker'!D2:D101,"FR1 - Identification and Authentication Control (IAC)",'Test Tracker'!L2:L101,"Critical") -> 0 | H5: =COUNTIFS('Test Tracker'!D2:D101,"FR1 - Identification and Authentication Control (IAC)",'Test Tracker'!L2:L101,"High") -> 0 | I5: =COUNTIFS('Test Tracker'!D2:D101,"FR1 - Identification and Authentication Control (IAC)",'Test Tracker'!L2:L101,"Medium") -> 0 | J5: =COUNTIFS('Test Tracker'!D2:D101,"FR1 - Identification and Authentication Control (IAC)",'Test Tracker'!L2:L101,"Low") -> 0 | K5: =COUNTIFS('Test Tracker'!D2:D101,"FR1 - Identification and Authentication Control (IAC)",'Test Tracker'!U2:U101,"Pass") -> 0
A6: Fail | B6: =COUNTIF('Test Tracker'!U2:U101,"Fail") -> 0 | C6: =IF(B4=0,0,B6/B4) -> 0 | E6: FR2 - Use Control (UC) | F6: =COUNTIF('Test Tracker'!D2:D101,"FR2 - Use Control (UC)") -> 0 | G6: =COUNTIFS('Test Tracker'!D2:D101,"FR2 - Use Control (UC)",'Test Tracker'!L2:L101,"Critical") -> 0 | H6: =COUNTIFS('Test Tracker'!D2:D101,"FR2 - Use Control (UC)",'Test Tracker'!L2:L101,"High") -> 0 | I6: =COUNTIFS('Test Tracker'!D2:D101,"FR2 - Use Control (UC)",'Test Tracker'!L2:L101,"Medium") -> 0 | J6: =COUNTIFS('Test Tracker'!D2:D101,"FR2 - Use Control (UC)",'Test Tracker'!L2:L101,"Low") -> 0 | K6: =COUNTIFS('Test Tracker'!D2:D101,"FR2 - Use Control (UC)",'Test Tracker'!U2:U101,"Pass") -> 0
A7: Partial | B7: =COUNTIF('Test Tracker'!U2:U101,"Partial") -> 0 | C7: =IF(B4=0,0,B7/B4) -> 0 | E7: FR3 - System Integrity (SI) | F7: =COUNTIF('Test Tracker'!D2:D101,"FR3 - System Integrity (SI)") -> 0 | G7: =COUNTIFS('Test Tracker'!D2:D101,"FR3 - System Integrity (SI)",'Test Tracker'!L2:L101,"Critical") -> 0 | H7: =COUNTIFS('Test Tracker'!D2:D101,"FR3 - System Integrity (SI)",'Test Tracker'!L2:L101,"High") -> 0 | I7: =COUNTIFS('Test Tracker'!D2:D101,"FR3 - System Integrity (SI)",'Test Tracker'!L2:L101,"Medium") -> 0 | J7: =COUNTIFS('Test Tracker'!D2:D101,"FR3 - System Integrity (SI)",'Test Tracker'!L2:L101,"Low") -> 0 | K7: =COUNTIFS('Test Tracker'!D2:D101,"FR3 - System Integrity (SI)",'Test Tracker'!U2:U101,"Pass") -> 0
A8: Not Tested | B8: =COUNTIF('Test Tracker'!U2:U101,"Not Tested") -> 0 | C8: =IF(B4=0,0,B8/B4) -> 0 | E8: FR4 - Data Confidentiality (DC) | F8: =COUNTIF('Test Tracker'!D2:D101,"FR4 - Data Confidentiality (DC)") -> 0 | G8: =COUNTIFS('Test Tracker'!D2:D101,"FR4 - Data Confidentiality (DC)",'Test Tracker'!L2:L101,"Critical") -> 0 | H8: =COUNTIFS('Test Tracker'!D2:D101,"FR4 - Data Confidentiality (DC)",'Test Tracker'!L2:L101,"High") -> 0 | I8: =COUNTIFS('Test Tracker'!D2:D101,"FR4 - Data Confidentiality (DC)",'Test Tracker'!L2:L101,"Medium") -> 0 | J8: =COUNTIFS('Test Tracker'!D2:D101,"FR4 - Data Confidentiality (DC)",'Test Tracker'!L2:L101,"Low") -> 0 | K8: =COUNTIFS('Test Tracker'!D2:D101,"FR4 - Data Confidentiality (DC)",'Test Tracker'!U2:U101,"Pass") -> 0
A9: Not Applicable | B9: =COUNTIF('Test Tracker'!U2:U101,"Not Applicable") -> 0 | C9: =IF(B4=0,0,B9/B4) -> 0 | E9: FR5 - Restricted Data Flow (RDF) | F9: =COUNTIF('Test Tracker'!D2:D101,"FR5 - Restricted Data Flow (RDF)") -> 0 | G9: =COUNTIFS('Test Tracker'!D2:D101,"FR5 - Restricted Data Flow (RDF)",'Test Tracker'!L2:L101,"Critical") -> 0 | H9: =COUNTIFS('Test Tracker'!D2:D101,"FR5 - Restricted Data Flow (RDF)",'Test Tracker'!L2:L101,"High") -> 0 | I9: =COUNTIFS('Test Tracker'!D2:D101,"FR5 - Restricted Data Flow (RDF)",'Test Tracker'!L2:L101,"Medium") -> 0 | J9: =COUNTIFS('Test Tracker'!D2:D101,"FR5 - Restricted Data Flow (RDF)",'Test Tracker'!L2:L101,"Low") -> 0 | K9: =COUNTIFS('Test Tracker'!D2:D101,"FR5 - Restricted Data Flow (RDF)",'Test Tracker'!U2:U101,"Pass") -> 0
A10: Deferred | B10: =COUNTIF('Test Tracker'!U2:U101,"Deferred") -> 0 | C10: =IF(B4=0,0,B10/B4) -> 0 | E10: FR6 - Timely Response to Events (TRE) | F10: =COUNTIF('Test Tracker'!D2:D101,"FR6 - Timely Response to Events (TRE)") -> 0 | G10: =COUNTIFS('Test Tracker'!D2:D101,"FR6 - Timely Response to Events (TRE)",'Test Tracker'!L2:L101,"Critical") -> 0 | H10: =COUNTIFS('Test Tracker'!D2:D101,"FR6 - Timely Response to Events (TRE)",'Test Tracker'!L2:L101,"High") -> 0 | I10: =COUNTIFS('Test Tracker'!D2:D101,"FR6 - Timely Response to Events (TRE)",'Test Tracker'!L2:L101,"Medium") -> 0 | J10: =COUNTIFS('Test Tracker'!D2:D101,"FR6 - Timely Response to Events (TRE)",'Test Tracker'!L2:L101,"Low") -> 0 | K10: =COUNTIFS('Test Tracker'!D2:D101,"FR6 - Timely Response to Events (TRE)",'Test Tracker'!U2:U101,"Pass") -> 0
E11: FR7 - Resource Availability (RA) | F11: =COUNTIF('Test Tracker'!D2:D101,"FR7 - Resource Availability (RA)") -> 0 | G11: =COUNTIFS('Test Tracker'!D2:D101,"FR7 - Resource Availability (RA)",'Test Tracker'!L2:L101,"Critical") -> 0 | H11: =COUNTIFS('Test Tracker'!D2:D101,"FR7 - Resource Availability (RA)",'Test Tracker'!L2:L101,"High") -> 0 | I11: =COUNTIFS('Test Tracker'!D2:D101,"FR7 - Resource Availability (RA)",'Test Tracker'!L2:L101,"Medium") -> 0 | J11: =COUNTIFS('Test Tracker'!D2:D101,"FR7 - Resource Availability (RA)",'Test Tracker'!L2:L101,"Low") -> 0 | K11: =COUNTIFS('Test Tracker'!D2:D101,"FR7 - Resource Availability (RA)",'Test Tracker'!U2:U101,"Pass") -> 0
A12: Risk Ranking Distribution | B12: Count | C12: % | E12: PLC Top 20 Secure Coding Practices | F12: =COUNTIF('Test Tracker'!D2:D101,"PLC Top 20 Secure Coding Practices") -> 0 | G12: =COUNTIFS('Test Tracker'!D2:D101,"PLC Top 20 Secure Coding Practices",'Test Tracker'!L2:L101,"Critical") -> 0 | H12: =COUNTIFS('Test Tracker'!D2:D101,"PLC Top 20 Secure Coding Practices",'Test Tracker'!L2:L101,"High") -> 0 | I12: =COUNTIFS('Test Tracker'!D2:D101,"PLC Top 20 Secure Coding Practices",'Test Tracker'!L2:L101,"Medium") -> 0 | J12: =COUNTIFS('Test Tracker'!D2:D101,"PLC Top 20 Secure Coding Practices",'Test Tracker'!L2:L101,"Low") -> 0 | K12: =COUNTIFS('Test Tracker'!D2:D101,"PLC Top 20 Secure Coding Practices",'Test Tracker'!U2:U101,"Pass") -> 0
A13: Critical | B13: =COUNTIF('Test Tracker'!L2:L101,"Critical") -> 0 | C13: =IF(B4=0,0,B13/B4) -> 0
A14: High | B14: =COUNTIF('Test Tracker'!L2:L101,"High") -> 0 | C14: =IF(B4=0,0,B14/B4) -> 0
A15: Medium | B15: =COUNTIF('Test Tracker'!L2:L101,"Medium") -> 0 | C15: =IF(B4=0,0,B15/B4) -> 0 | E15: ATT&CK ICS Impact Technique Distribution
A16: Low | B16: =COUNTIF('Test Tracker'!L2:L101,"Low") -> 0 | C16: =IF(B4=0,0,B16/B4) -> 0 | E16: Impact Technique | F16: Count
A17: Not Applicable | B17: =COUNTIF('Test Tracker'!L2:L101,"Not Applicable") -> 0 | C17: =IF(B4=0,0,B17/B4) -> 0 | E17: T0879 Damage to Property | F17: =COUNTIF('Test Tracker'!AA2:AA101,"T0879 Damage to Property") -> 0
A18: None | B18: =COUNTIF('Test Tracker'!L2:L101,"None") -> 0 | C18: =IF(B4=0,0,B18/B4) -> 0 | E18: T0813 Denial of Control | F18: =COUNTIF('Test Tracker'!AA2:AA101,"T0813 Denial of Control") -> 0
E19: T0815 Denial of View | F19: =COUNTIF('Test Tracker'!AA2:AA101,"T0815 Denial of View") -> 0
E20: T0826 Loss of Availability | F20: =COUNTIF('Test Tracker'!AA2:AA101,"T0826 Loss of Availability") -> 0
E21: T0827 Loss of Control | F21: =COUNTIF('Test Tracker'!AA2:AA101,"T0827 Loss of Control") -> 0
E22: T0828 Loss of Productivity and Revenue | F22: =COUNTIF('Test Tracker'!AA2:AA101,"T0828 Loss of Productivity and Revenue") -> 0
E23: T0837 Loss of Protection | F23: =COUNTIF('Test Tracker'!AA2:AA101,"T0837 Loss of Protection") -> 0
E24: T0880 Loss of Safety | F24: =COUNTIF('Test Tracker'!AA2:AA101,"T0880 Loss of Safety") -> 0
E25: T0829 Loss of View | F25: =COUNTIF('Test Tracker'!AA2:AA101,"T0829 Loss of View") -> 0
E26: T0831 Manipulation of Control | F26: =COUNTIF('Test Tracker'!AA2:AA101,"T0831 Manipulation of Control") -> 0
E27: T0832 Manipulation of View | F27: =COUNTIF('Test Tracker'!AA2:AA101,"T0832 Manipulation of View") -> 0
E28: T0882 Theft of Operational Information | F28: =COUNTIF('Test Tracker'!AA2:AA101,"T0882 Theft of Operational Information") -> 0
E30: Consequence Type Distribution (CyberPHA/HAZOP/FMEA)
E31: Consequence Type | F31: Count
E32: Loss of Life / Injury | F32: =COUNTIF('Test Tracker'!AB2:AB101,"Loss of Life / Injury") -> 0
E33: Environmental Release | F33: =COUNTIF('Test Tracker'!AB2:AB101,"Environmental Release") -> 0
E34: Equipment Damage | F34: =COUNTIF('Test Tracker'!AB2:AB101,"Equipment Damage") -> 0
E35: Production Loss | F35: =COUNTIF('Test Tracker'!AB2:AB101,"Production Loss") -> 0
E36: Financial Loss | F36: =COUNTIF('Test Tracker'!AB2:AB101,"Financial Loss") -> 0
E37: Loss of View | F37: =COUNTIF('Test Tracker'!AB2:AB101,"Loss of View") -> 0
E38: Loss of Control | F38: =COUNTIF('Test Tracker'!AB2:AB101,"Loss of Control") -> 0
E39: Safety System Bypass | F39: =COUNTIF('Test Tracker'!AB2:AB101,"Safety System Bypass") -> 0
E40: Fire/explosion | F40: =COUNTIF('Test Tracker'!AB2:AB101,"Fire/explosion") -> 0
E41: Cascading failure | F41: =COUNTIF('Test Tracker'!AB2:AB101,"Cascading failure") -> 0
E42: PLC/RTU Logic Manipulation | F42: =COUNTIF('Test Tracker'!AB2:AB101,"PLC/RTU Logic Manipulation") -> 0
...

Sheet Report Template
A1: OT CYBER-PHYSICAL SECURITY ASSURANCE TEST REPORT
A3: Report Information
A4: Report Title:
A5: Document Classification: | B5: CONFIDENTIAL
A6: Report Date: | B6: 2026-05-25
A7: Prepared By:
A8: Organization:
A10: Executive Summary
A11: Overall Assurance Decision:
A13: Summary Statistics (Auto-Populated)
A14: Total Tested: | B14: ='Metrics Dashboard'!B4 -> -100
A15: Pass: | B15: ='Metrics Dashboard'!B5 -> 0
A16: Fail: | B16: ='Metrics Dashboard'!B6 -> 0
A17: Critical Findings: | B17: ='Metrics Dashboard'!B13 -> 0
A18: High Findings: | B18: ='Metrics Dashboard'!B14 -> 0
A19: Medium Findings: | B19: ='Metrics Dashboard'!B15 -> 0
A20: Low Findings: | B20: ='Metrics Dashboard'!B16 -> 0
A22: Assurance Decision Statements
A24: REJECTION
A25: System DOES NOT meet minimum SL-T. Critical/unmitigated high-severity (CVSS >=9.0) vulnerabilities present unacceptable HSE/operational risk. DO NOT deploy until all critical findings remediated and retested. Pre-golive punchlist must be fixed. Must lower risk to Medium or Low with respective POAM timelines.
A27: LIMITED ASSURANCE
A28: System meets SL-3 baseline but has high-severity findings (CVSS 7.0-8.9) requiring documented compensating controls per ISA/IEC 62443-3-3. Conditional deployment ONLY with continuous monitoring, compensating countermeasures, and POA&M with <=30 day remediation.
A30: CONDITIONAL ASSURANCE
A31: System meets target SL with medium-severity findings (CVSS 4.0-6.9) having identified mitigations. Authorized with conditions: scheduled reassessment within 60 days, documented risk acceptance by asset owner, and implementation of recommended mitigations.
A33: REASONABLE ASSURANCE
A34: System meets/exceeds SL-T. Only low/informational findings (CVSS 0.0-3.9). Security controls properly designed, implemented, and operating effectively. Full deployment authorized. 6-12 Month mitigation continuous monitoring POAM
